# backend/auth.py

from datetime import datetime, timedelta
from typing import Optional

from jose import JWTError, jwt
from fastapi import Depends, HTTPException, status
from fastapi.security import OAuth2PasswordBearer
from passlib.context import CryptContext

from backend.config import settings
from backend.database import get_db
from backend import models
from sqlalchemy.orm import Session

pwd_context = CryptContext(schemes=["bcrypt"], deprecated="auto")

oauth2_scheme = OAuth2PasswordBearer(tokenUrl="/user/login")


def hash_password(password: str) -> str:
    return pwd_context.hash(password)


def verify_password(plain_password: str, hashed_password: str) -> bool:
    return pwd_context.verify(plain_password, hashed_password)


def create_access_token(data: dict, expires_delta: Optional[timedelta] = None) -> str:
    to_encode = data.copy()
    expire = datetime.utcnow() + (expires_delta or timedelta(minutes=settings.ACCESS_TOKEN_EXPIRE_MINUTES))
    to_encode.update({"exp": expire})
    return jwt.encode(to_encode, settings.SECRET_KEY, algorithm=settings.ALGORITHM)


def decode_token(token: str) -> Optional[dict]:
    try:
        return jwt.decode(token, settings.SECRET_KEY, algorithms=[settings.ALGORITHM])
    except JWTError:
        return None


# âœ… Add this function to fix the error
def get_current_user(token: str = Depends(oauth2_scheme), db: Session = Depends(get_db)):
    credentials_exception = HTTPException(
        status_code=status.HTTP_401_UNAUTHORIZED,
        detail="Could not validate credentials"
    )
    try:
        payload = jwt.decode(token, settings.SECRET_KEY, algorithms=[settings.ALGORITHM])
        email: str = payload.get("sub")
        if email is None:
            raise credentials_exception
    except JWTError:
        raise credentials_exception

    user = db.query(models.User).filter(models.User.email == email).first()
    if user is None:
        raise credentials_exception
    return user
